{
 "cells": [
  {
   "cell_type": "code",
   "execution_count": 1,
   "metadata": {
    "collapsed": true,
    "ExecuteTime": {
     "end_time": "2023-06-06T10:19:27.908280600Z",
     "start_time": "2023-06-06T10:19:25.311695Z"
    }
   },
   "outputs": [
    {
     "name": "stderr",
     "output_type": "stream",
     "text": [
      "C:\\Users\\Isabe\\.julia\\conda\\3\\envs\\newxai\\lib\\site-packages\\shap\\utils\\_clustering.py:35: NumbaDeprecationWarning: \u001B[1mThe 'nopython' keyword argument was not supplied to the 'numba.jit' decorator. The implicit default value for this argument is currently False, but it will be changed to True in Numba 0.59.0. See https://numba.readthedocs.io/en/stable/reference/deprecation.html#deprecation-of-object-mode-fall-back-behaviour-when-using-jit for details.\u001B[0m\n",
      "  def _pt_shuffle_rec(i, indexes, index_mask, partition_tree, M, pos):\n",
      "C:\\Users\\Isabe\\.julia\\conda\\3\\envs\\newxai\\lib\\site-packages\\shap\\utils\\_clustering.py:54: NumbaDeprecationWarning: \u001B[1mThe 'nopython' keyword argument was not supplied to the 'numba.jit' decorator. The implicit default value for this argument is currently False, but it will be changed to True in Numba 0.59.0. See https://numba.readthedocs.io/en/stable/reference/deprecation.html#deprecation-of-object-mode-fall-back-behaviour-when-using-jit for details.\u001B[0m\n",
      "  def delta_minimization_order(all_masks, max_swap_size=100, num_passes=2):\n",
      "C:\\Users\\Isabe\\.julia\\conda\\3\\envs\\newxai\\lib\\site-packages\\shap\\utils\\_clustering.py:63: NumbaDeprecationWarning: \u001B[1mThe 'nopython' keyword argument was not supplied to the 'numba.jit' decorator. The implicit default value for this argument is currently False, but it will be changed to True in Numba 0.59.0. See https://numba.readthedocs.io/en/stable/reference/deprecation.html#deprecation-of-object-mode-fall-back-behaviour-when-using-jit for details.\u001B[0m\n",
      "  def _reverse_window(order, start, length):\n",
      "C:\\Users\\Isabe\\.julia\\conda\\3\\envs\\newxai\\lib\\site-packages\\shap\\utils\\_clustering.py:69: NumbaDeprecationWarning: \u001B[1mThe 'nopython' keyword argument was not supplied to the 'numba.jit' decorator. The implicit default value for this argument is currently False, but it will be changed to True in Numba 0.59.0. See https://numba.readthedocs.io/en/stable/reference/deprecation.html#deprecation-of-object-mode-fall-back-behaviour-when-using-jit for details.\u001B[0m\n",
      "  def _reverse_window_score_gain(masks, order, start, length):\n",
      "C:\\Users\\Isabe\\.julia\\conda\\3\\envs\\newxai\\lib\\site-packages\\shap\\utils\\_clustering.py:77: NumbaDeprecationWarning: \u001B[1mThe 'nopython' keyword argument was not supplied to the 'numba.jit' decorator. The implicit default value for this argument is currently False, but it will be changed to True in Numba 0.59.0. See https://numba.readthedocs.io/en/stable/reference/deprecation.html#deprecation-of-object-mode-fall-back-behaviour-when-using-jit for details.\u001B[0m\n",
      "  def _mask_delta_score(m1, m2):\n",
      "C:\\Users\\Isabe\\.julia\\conda\\3\\envs\\newxai\\lib\\site-packages\\shap\\links.py:5: NumbaDeprecationWarning: \u001B[1mThe 'nopython' keyword argument was not supplied to the 'numba.jit' decorator. The implicit default value for this argument is currently False, but it will be changed to True in Numba 0.59.0. See https://numba.readthedocs.io/en/stable/reference/deprecation.html#deprecation-of-object-mode-fall-back-behaviour-when-using-jit for details.\u001B[0m\n",
      "  def identity(x):\n",
      "C:\\Users\\Isabe\\.julia\\conda\\3\\envs\\newxai\\lib\\site-packages\\shap\\links.py:10: NumbaDeprecationWarning: \u001B[1mThe 'nopython' keyword argument was not supplied to the 'numba.jit' decorator. The implicit default value for this argument is currently False, but it will be changed to True in Numba 0.59.0. See https://numba.readthedocs.io/en/stable/reference/deprecation.html#deprecation-of-object-mode-fall-back-behaviour-when-using-jit for details.\u001B[0m\n",
      "  def _identity_inverse(x):\n",
      "C:\\Users\\Isabe\\.julia\\conda\\3\\envs\\newxai\\lib\\site-packages\\shap\\links.py:15: NumbaDeprecationWarning: \u001B[1mThe 'nopython' keyword argument was not supplied to the 'numba.jit' decorator. The implicit default value for this argument is currently False, but it will be changed to True in Numba 0.59.0. See https://numba.readthedocs.io/en/stable/reference/deprecation.html#deprecation-of-object-mode-fall-back-behaviour-when-using-jit for details.\u001B[0m\n",
      "  def logit(x):\n",
      "C:\\Users\\Isabe\\.julia\\conda\\3\\envs\\newxai\\lib\\site-packages\\shap\\links.py:20: NumbaDeprecationWarning: \u001B[1mThe 'nopython' keyword argument was not supplied to the 'numba.jit' decorator. The implicit default value for this argument is currently False, but it will be changed to True in Numba 0.59.0. See https://numba.readthedocs.io/en/stable/reference/deprecation.html#deprecation-of-object-mode-fall-back-behaviour-when-using-jit for details.\u001B[0m\n",
      "  def _logit_inverse(x):\n",
      "C:\\Users\\Isabe\\.julia\\conda\\3\\envs\\newxai\\lib\\site-packages\\shap\\utils\\_masked_model.py:363: NumbaDeprecationWarning: \u001B[1mThe 'nopython' keyword argument was not supplied to the 'numba.jit' decorator. The implicit default value for this argument is currently False, but it will be changed to True in Numba 0.59.0. See https://numba.readthedocs.io/en/stable/reference/deprecation.html#deprecation-of-object-mode-fall-back-behaviour-when-using-jit for details.\u001B[0m\n",
      "  def _build_fixed_single_output(averaged_outs, last_outs, outputs, batch_positions, varying_rows, num_varying_rows, link, linearizing_weights):\n",
      "C:\\Users\\Isabe\\.julia\\conda\\3\\envs\\newxai\\lib\\site-packages\\shap\\utils\\_masked_model.py:385: NumbaDeprecationWarning: \u001B[1mThe 'nopython' keyword argument was not supplied to the 'numba.jit' decorator. The implicit default value for this argument is currently False, but it will be changed to True in Numba 0.59.0. See https://numba.readthedocs.io/en/stable/reference/deprecation.html#deprecation-of-object-mode-fall-back-behaviour-when-using-jit for details.\u001B[0m\n",
      "  def _build_fixed_multi_output(averaged_outs, last_outs, outputs, batch_positions, varying_rows, num_varying_rows, link, linearizing_weights):\n",
      "C:\\Users\\Isabe\\.julia\\conda\\3\\envs\\newxai\\lib\\site-packages\\shap\\utils\\_masked_model.py:428: NumbaDeprecationWarning: \u001B[1mThe 'nopython' keyword argument was not supplied to the 'numba.jit' decorator. The implicit default value for this argument is currently False, but it will be changed to True in Numba 0.59.0. See https://numba.readthedocs.io/en/stable/reference/deprecation.html#deprecation-of-object-mode-fall-back-behaviour-when-using-jit for details.\u001B[0m\n",
      "  def _init_masks(cluster_matrix, M, indices_row_pos, indptr):\n",
      "C:\\Users\\Isabe\\.julia\\conda\\3\\envs\\newxai\\lib\\site-packages\\shap\\utils\\_masked_model.py:439: NumbaDeprecationWarning: \u001B[1mThe 'nopython' keyword argument was not supplied to the 'numba.jit' decorator. The implicit default value for this argument is currently False, but it will be changed to True in Numba 0.59.0. See https://numba.readthedocs.io/en/stable/reference/deprecation.html#deprecation-of-object-mode-fall-back-behaviour-when-using-jit for details.\u001B[0m\n",
      "  def _rec_fill_masks(cluster_matrix, indices_row_pos, indptr, indices, M, ind):\n",
      "C:\\Users\\Isabe\\.julia\\conda\\3\\envs\\newxai\\lib\\site-packages\\shap\\maskers\\_tabular.py:186: NumbaDeprecationWarning: \u001B[1mThe 'nopython' keyword argument was not supplied to the 'numba.jit' decorator. The implicit default value for this argument is currently False, but it will be changed to True in Numba 0.59.0. See https://numba.readthedocs.io/en/stable/reference/deprecation.html#deprecation-of-object-mode-fall-back-behaviour-when-using-jit for details.\u001B[0m\n",
      "  def _single_delta_mask(dind, masked_inputs, last_mask, data, x, noop_code):\n",
      "C:\\Users\\Isabe\\.julia\\conda\\3\\envs\\newxai\\lib\\site-packages\\shap\\maskers\\_tabular.py:197: NumbaDeprecationWarning: \u001B[1mThe 'nopython' keyword argument was not supplied to the 'numba.jit' decorator. The implicit default value for this argument is currently False, but it will be changed to True in Numba 0.59.0. See https://numba.readthedocs.io/en/stable/reference/deprecation.html#deprecation-of-object-mode-fall-back-behaviour-when-using-jit for details.\u001B[0m\n",
      "  def _delta_masking(masks, x, curr_delta_inds, varying_rows_out,\n",
      "C:\\Users\\Isabe\\.julia\\conda\\3\\envs\\newxai\\lib\\site-packages\\shap\\maskers\\_image.py:175: NumbaDeprecationWarning: \u001B[1mThe 'nopython' keyword argument was not supplied to the 'numba.jit' decorator. The implicit default value for this argument is currently False, but it will be changed to True in Numba 0.59.0. See https://numba.readthedocs.io/en/stable/reference/deprecation.html#deprecation-of-object-mode-fall-back-behaviour-when-using-jit for details.\u001B[0m\n",
      "  def _jit_build_partition_tree(xmin, xmax, ymin, ymax, zmin, zmax, total_ywidth, total_zwidth, M, clustering, q):\n",
      "C:\\Users\\Isabe\\.julia\\conda\\3\\envs\\newxai\\lib\\site-packages\\shap\\explainers\\_partition.py:676: NumbaDeprecationWarning: \u001B[1mThe 'nopython' keyword argument was not supplied to the 'numba.jit' decorator. The implicit default value for this argument is currently False, but it will be changed to True in Numba 0.59.0. See https://numba.readthedocs.io/en/stable/reference/deprecation.html#deprecation-of-object-mode-fall-back-behaviour-when-using-jit for details.\u001B[0m\n",
      "  def lower_credit(i, value, M, values, clustering):\n",
      "\u001B[1mThe 'nopython' keyword argument was not supplied to the 'numba.jit' decorator. The implicit default value for this argument is currently False, but it will be changed to True in Numba 0.59.0. See https://numba.readthedocs.io/en/stable/reference/deprecation.html#deprecation-of-object-mode-fall-back-behaviour-when-using-jit for details.\u001B[0m\n",
      "\u001B[1mThe 'nopython' keyword argument was not supplied to the 'numba.jit' decorator. The implicit default value for this argument is currently False, but it will be changed to True in Numba 0.59.0. See https://numba.readthedocs.io/en/stable/reference/deprecation.html#deprecation-of-object-mode-fall-back-behaviour-when-using-jit for details.\u001B[0m\n"
     ]
    }
   ],
   "source": [
    "%load_ext autoreload\n",
    "%autoreload 2\n",
    "from model import ExplainableModel\n",
    "from sklearn.model_selection import train_test_split\n",
    "from explanationplots import *\n"
   ]
  },
  {
   "cell_type": "code",
   "execution_count": 2,
   "outputs": [],
   "source": [
    "def get_data():\n",
    "    df = pd.read_csv(\"data/paysim.csv\")\n",
    "    df = df.drop(\"isFlaggedFraud\", axis=1)\n",
    "\n",
    "    df = df.drop(['nameOrig', 'nameDest'], axis=1)\n",
    "    df = pd.get_dummies(df, columns=['type'])\n",
    "\n",
    "    train, test = train_test_split(df, test_size=0.1, stratify=df[\"isFraud\"])\n",
    "    x_train, y_train = train.drop(['isFraud'], axis=1), train[\"isFraud\"]\n",
    "    x_test, y_test = test.drop(['isFraud'], axis=1), test[\"isFraud\"]\n",
    "\n",
    "    return x_train, y_train, x_test, y_test"
   ],
   "metadata": {
    "collapsed": false,
    "ExecuteTime": {
     "end_time": "2023-06-06T10:19:28.004998100Z",
     "start_time": "2023-06-06T10:19:27.913295500Z"
    }
   }
  },
  {
   "cell_type": "code",
   "execution_count": 3,
   "outputs": [],
   "source": [
    "x_train, y_train, x_test, y_test = get_data()\n",
    "\n",
    "params = {\"objective\": \"binary:logistic\",\n",
    "          \"verbosity\": 1,\n",
    "          \"tree_method\": \"gpu_hist\"}\n",
    "\n",
    "model = ExplainableModel(x_train, y_train, params=params,\n",
    "                         path=\"./weights/model.pkl\",\n",
    "                         explainer_path=\"./weights/explainer.pkl\",\n",
    "                         seed=42)\n",
    "\n",
    "# model.train(iterations=300, do_train=False, load=True, save=False)\n",
    "y_hat = model.predict(x_test)"
   ],
   "metadata": {
    "collapsed": false,
    "ExecuteTime": {
     "end_time": "2023-06-06T10:19:53.049866700Z",
     "start_time": "2023-06-06T10:19:28.006010700Z"
    }
   }
  },
  {
   "cell_type": "code",
   "execution_count": 5,
   "outputs": [
    {
     "name": "stderr",
     "output_type": "stream",
     "text": [
      "Traceback (most recent call last):\n",
      "  File \"_pydevd_bundle\\pydevd_cython_win32_39_64.pyx\", line 1548, in _pydevd_bundle.pydevd_cython_win32_39_64.ThreadTracer.__call__\n",
      "KeyError: 'C:\\\\Program Files\\\\JetBrains\\\\PyCharm 2022.3.1\\\\plugins\\\\python\\\\helpers\\\\pydev\\\\pydevd_file_utils.py'\n",
      "\n",
      "During handling of the above exception, another exception occurred:\n",
      "\n",
      "Traceback (most recent call last):\n",
      "  File \"C:\\Program Files\\JetBrains\\PyCharm 2022.3.1\\plugins\\python\\helpers\\pydev\\pydevd_file_utils.py\", line 586, in get_abs_path_real_path_and_base_from_frame\n",
      "    return NORM_PATHS_AND_BASE_CONTAINER[frame.f_code.co_filename]\n",
      "NameError: name 'NORM_PATHS_AND_BASE_CONTAINER' is not defined\n",
      "\n",
      "During handling of the above exception, another exception occurred:\n",
      "\n",
      "Traceback (most recent call last):\n",
      "  File \"_pydevd_bundle\\pydevd_cython_win32_39_64.pyx\", line 1550, in _pydevd_bundle.pydevd_cython_win32_39_64.ThreadTracer.__call__\n",
      "  File \"C:\\Program Files\\JetBrains\\PyCharm 2022.3.1\\plugins\\python\\helpers\\pydev\\pydevd_file_utils.py\", line 593, in get_abs_path_real_path_and_base_from_frame\n",
      "    if get_abs_path_real_path_and_base_from_file is None:  # Interpreter shutdown\n",
      "NameError: name 'get_abs_path_real_path_and_base_from_file' is not defined\n",
      "Traceback (most recent call last):\n",
      "  File \"_pydevd_bundle\\pydevd_cython_win32_39_64.pyx\", line 1548, in _pydevd_bundle.pydevd_cython_win32_39_64.ThreadTracer.__call__\n",
      "KeyError: 'C:\\\\Program Files\\\\JetBrains\\\\PyCharm 2022.3.1\\\\plugins\\\\python\\\\helpers\\\\pydev\\\\pydevd_file_utils.py'\n",
      "\n",
      "During handling of the above exception, another exception occurred:\n",
      "\n",
      "Traceback (most recent call last):\n",
      "  File \"C:\\Program Files\\JetBrains\\PyCharm 2022.3.1\\plugins\\python\\helpers\\pydev\\pydevd_file_utils.py\", line 586, in get_abs_path_real_path_and_base_from_frame\n",
      "    return NORM_PATHS_AND_BASE_CONTAINER[frame.f_code.co_filename]\n",
      "NameError: name 'NORM_PATHS_AND_BASE_CONTAINER' is not defined\n",
      "\n",
      "During handling of the above exception, another exception occurred:\n",
      "\n",
      "Traceback (most recent call last):\n",
      "  File \"_pydevd_bundle\\pydevd_cython_win32_39_64.pyx\", line 1550, in _pydevd_bundle.pydevd_cython_win32_39_64.ThreadTracer.__call__\n",
      "  File \"C:\\Program Files\\JetBrains\\PyCharm 2022.3.1\\plugins\\python\\helpers\\pydev\\pydevd_file_utils.py\", line 593, in get_abs_path_real_path_and_base_from_frame\n",
      "    if get_abs_path_real_path_and_base_from_file is None:  # Interpreter shutdown\n",
      "NameError: name 'get_abs_path_real_path_and_base_from_file' is not defined\n",
      "Traceback (most recent call last):\n",
      "  File \"_pydevd_bundle\\pydevd_cython_win32_39_64.pyx\", line 1548, in _pydevd_bundle.pydevd_cython_win32_39_64.ThreadTracer.__call__\n",
      "KeyError: 'C:\\\\Program Files\\\\JetBrains\\\\PyCharm 2022.3.1\\\\plugins\\\\python\\\\helpers\\\\pydev\\\\pydevd_file_utils.py'\n",
      "\n",
      "During handling of the above exception, another exception occurred:\n",
      "\n",
      "Traceback (most recent call last):\n",
      "  File \"C:\\Program Files\\JetBrains\\PyCharm 2022.3.1\\plugins\\python\\helpers\\pydev\\pydevd_file_utils.py\", line 586, in get_abs_path_real_path_and_base_from_frame\n",
      "    return NORM_PATHS_AND_BASE_CONTAINER[frame.f_code.co_filename]\n",
      "NameError: name 'NORM_PATHS_AND_BASE_CONTAINER' is not defined\n",
      "\n",
      "During handling of the above exception, another exception occurred:\n",
      "\n",
      "Traceback (most recent call last):\n",
      "  File \"_pydevd_bundle\\pydevd_cython_win32_39_64.pyx\", line 1550, in _pydevd_bundle.pydevd_cython_win32_39_64.ThreadTracer.__call__\n",
      "  File \"C:\\Program Files\\JetBrains\\PyCharm 2022.3.1\\plugins\\python\\helpers\\pydev\\pydevd_file_utils.py\", line 593, in get_abs_path_real_path_and_base_from_frame\n",
      "    if get_abs_path_real_path_and_base_from_file is None:  # Interpreter shutdown\n",
      "NameError: name 'get_abs_path_real_path_and_base_from_file' is not defined\n",
      "Traceback (most recent call last):\n",
      "  File \"_pydevd_bundle\\pydevd_cython_win32_39_64.pyx\", line 1548, in _pydevd_bundle.pydevd_cython_win32_39_64.ThreadTracer.__call__\n",
      "KeyError: 'C:\\\\Program Files\\\\JetBrains\\\\PyCharm 2022.3.1\\\\plugins\\\\python\\\\helpers\\\\pydev\\\\pydevd_file_utils.py'\n",
      "\n",
      "During handling of the above exception, another exception occurred:\n",
      "\n",
      "Traceback (most recent call last):\n",
      "  File \"C:\\Program Files\\JetBrains\\PyCharm 2022.3.1\\plugins\\python\\helpers\\pydev\\pydevd_file_utils.py\", line 586, in get_abs_path_real_path_and_base_from_frame\n",
      "    return NORM_PATHS_AND_BASE_CONTAINER[frame.f_code.co_filename]\n",
      "NameError: name 'NORM_PATHS_AND_BASE_CONTAINER' is not defined\n",
      "\n",
      "During handling of the above exception, another exception occurred:\n",
      "\n",
      "Traceback (most recent call last):\n",
      "  File \"_pydevd_bundle\\pydevd_cython_win32_39_64.pyx\", line 1550, in _pydevd_bundle.pydevd_cython_win32_39_64.ThreadTracer.__call__\n",
      "  File \"C:\\Program Files\\JetBrains\\PyCharm 2022.3.1\\plugins\\python\\helpers\\pydev\\pydevd_file_utils.py\", line 593, in get_abs_path_real_path_and_base_from_frame\n",
      "    if get_abs_path_real_path_and_base_from_file is None:  # Interpreter shutdown\n",
      "NameError: name 'get_abs_path_real_path_and_base_from_file' is not defined\n",
      "Traceback (most recent call last):\n",
      "  File \"_pydevd_bundle\\pydevd_cython_win32_39_64.pyx\", line 1548, in _pydevd_bundle.pydevd_cython_win32_39_64.ThreadTracer.__call__\n",
      "KeyError: 'C:\\\\Program Files\\\\JetBrains\\\\PyCharm 2022.3.1\\\\plugins\\\\python\\\\helpers\\\\pydev\\\\pydevd_file_utils.py'\n",
      "\n",
      "During handling of the above exception, another exception occurred:\n",
      "\n",
      "Traceback (most recent call last):\n",
      "  File \"C:\\Program Files\\JetBrains\\PyCharm 2022.3.1\\plugins\\python\\helpers\\pydev\\pydevd_file_utils.py\", line 586, in get_abs_path_real_path_and_base_from_frame\n",
      "    return NORM_PATHS_AND_BASE_CONTAINER[frame.f_code.co_filename]\n",
      "NameError: name 'NORM_PATHS_AND_BASE_CONTAINER' is not defined\n",
      "\n",
      "During handling of the above exception, another exception occurred:\n",
      "\n",
      "Traceback (most recent call last):\n",
      "  File \"_pydevd_bundle\\pydevd_cython_win32_39_64.pyx\", line 1550, in _pydevd_bundle.pydevd_cython_win32_39_64.ThreadTracer.__call__\n",
      "  File \"C:\\Program Files\\JetBrains\\PyCharm 2022.3.1\\plugins\\python\\helpers\\pydev\\pydevd_file_utils.py\", line 593, in get_abs_path_real_path_and_base_from_frame\n",
      "    if get_abs_path_real_path_and_base_from_file is None:  # Interpreter shutdown\n",
      "NameError: name 'get_abs_path_real_path_and_base_from_file' is not defined\n",
      "Traceback (most recent call last):\n",
      "  File \"_pydevd_bundle\\pydevd_cython_win32_39_64.pyx\", line 1548, in _pydevd_bundle.pydevd_cython_win32_39_64.ThreadTracer.__call__\n",
      "KeyError: 'C:\\\\Program Files\\\\JetBrains\\\\PyCharm 2022.3.1\\\\plugins\\\\python\\\\helpers\\\\pydev\\\\pydevd_file_utils.py'\n",
      "\n",
      "During handling of the above exception, another exception occurred:\n",
      "\n",
      "Traceback (most recent call last):\n",
      "  File \"C:\\Program Files\\JetBrains\\PyCharm 2022.3.1\\plugins\\python\\helpers\\pydev\\pydevd_file_utils.py\", line 586, in get_abs_path_real_path_and_base_from_frame\n",
      "    return NORM_PATHS_AND_BASE_CONTAINER[frame.f_code.co_filename]\n",
      "KeyError: 'C:\\\\Program Files\\\\JetBrains\\\\PyCharm 2022.3.1\\\\plugins\\\\python\\\\helpers\\\\pydev\\\\pydevd_file_utils.py'\n",
      "\n",
      "During handling of the above exception, another exception occurred:\n",
      "\n",
      "Traceback (most recent call last):\n",
      "  File \"_pydevd_bundle\\pydevd_cython_win32_39_64.pyx\", line 1550, in _pydevd_bundle.pydevd_cython_win32_39_64.ThreadTracer.__call__\n",
      "  File \"C:\\Program Files\\JetBrains\\PyCharm 2022.3.1\\plugins\\python\\helpers\\pydev\\pydevd_file_utils.py\", line 593, in get_abs_path_real_path_and_base_from_frame\n",
      "    if get_abs_path_real_path_and_base_from_file is None:  # Interpreter shutdown\n",
      "NameError: name 'get_abs_path_real_path_and_base_from_file' is not defined\n",
      "Traceback (most recent call last):\n",
      "  File \"_pydevd_bundle\\pydevd_cython_win32_39_64.pyx\", line 1548, in _pydevd_bundle.pydevd_cython_win32_39_64.ThreadTracer.__call__\n",
      "KeyError: 'C:\\\\Program Files\\\\JetBrains\\\\PyCharm 2022.3.1\\\\plugins\\\\python\\\\helpers\\\\pydev\\\\pydevd_file_utils.py'\n",
      "\n",
      "During handling of the above exception, another exception occurred:\n",
      "\n",
      "Traceback (most recent call last):\n",
      "  File \"C:\\Program Files\\JetBrains\\PyCharm 2022.3.1\\plugins\\python\\helpers\\pydev\\pydevd_file_utils.py\", line 586, in get_abs_path_real_path_and_base_from_frame\n",
      "    return NORM_PATHS_AND_BASE_CONTAINER[frame.f_code.co_filename]\n",
      "KeyError: 'C:\\\\Program Files\\\\JetBrains\\\\PyCharm 2022.3.1\\\\plugins\\\\python\\\\helpers\\\\pydev\\\\pydevd_file_utils.py'\n",
      "\n",
      "During handling of the above exception, another exception occurred:\n",
      "\n",
      "Traceback (most recent call last):\n",
      "  File \"_pydevd_bundle\\pydevd_cython_win32_39_64.pyx\", line 1550, in _pydevd_bundle.pydevd_cython_win32_39_64.ThreadTracer.__call__\n",
      "  File \"C:\\Program Files\\JetBrains\\PyCharm 2022.3.1\\plugins\\python\\helpers\\pydev\\pydevd_file_utils.py\", line 593, in get_abs_path_real_path_and_base_from_frame\n",
      "    if get_abs_path_real_path_and_base_from_file is None:  # Interpreter shutdown\n",
      "NameError: name 'get_abs_path_real_path_and_base_from_file' is not defined\n",
      "Traceback (most recent call last):\n",
      "  File \"C:\\Program Files\\JetBrains\\PyCharm 2022.3.1\\plugins\\python\\helpers\\pydev\\pydevd_file_utils.py\", line 230, in _NormPaths\n",
      "    return NORM_PATHS_CONTAINER[filename]\n",
      "KeyError: 'C:\\\\Users\\\\Isabe\\\\.julia\\\\conda\\\\3\\\\envs\\\\newxai\\\\lib\\\\ntpath.py'\n",
      "\n",
      "During handling of the above exception, another exception occurred:\n",
      "\n",
      "Traceback (most recent call last):\n",
      "  File \"_pydevd_bundle\\pydevd_cython_win32_39_64.pyx\", line 1548, in _pydevd_bundle.pydevd_cython_win32_39_64.ThreadTracer.__call__\n",
      "KeyError: 'C:\\\\Program Files\\\\JetBrains\\\\PyCharm 2022.3.1\\\\plugins\\\\python\\\\helpers\\\\pydev\\\\pydevd_file_utils.py'\n",
      "\n",
      "During handling of the above exception, another exception occurred:\n",
      "\n",
      "Traceback (most recent call last):\n",
      "  File \"C:\\Program Files\\JetBrains\\PyCharm 2022.3.1\\plugins\\python\\helpers\\pydev\\pydevd_file_utils.py\", line 586, in get_abs_path_real_path_and_base_from_frame\n",
      "    return NORM_PATHS_AND_BASE_CONTAINER[frame.f_code.co_filename]\n",
      "KeyError: 'C:\\\\Program Files\\\\JetBrains\\\\PyCharm 2022.3.1\\\\plugins\\\\python\\\\helpers\\\\pydev\\\\pydevd_file_utils.py'\n",
      "\n",
      "During handling of the above exception, another exception occurred:\n",
      "\n",
      "Traceback (most recent call last):\n",
      "  File \"_pydevd_bundle\\pydevd_cython_win32_39_64.pyx\", line 1550, in _pydevd_bundle.pydevd_cython_win32_39_64.ThreadTracer.__call__\n",
      "  File \"C:\\Program Files\\JetBrains\\PyCharm 2022.3.1\\plugins\\python\\helpers\\pydev\\pydevd_file_utils.py\", line 593, in get_abs_path_real_path_and_base_from_frame\n",
      "    if get_abs_path_real_path_and_base_from_file is None:  # Interpreter shutdown\n",
      "NameError: name 'get_abs_path_real_path_and_base_from_file' is not defined\n",
      "Traceback (most recent call last):\n",
      "  File \"C:\\Program Files\\JetBrains\\PyCharm 2022.3.1\\plugins\\python\\helpers\\pydev\\pydevd_file_utils.py\", line 230, in _NormPaths\n",
      "    return NORM_PATHS_CONTAINER[filename]\n",
      "KeyError: 'C:\\\\Users\\\\Isabe\\\\.julia\\\\conda\\\\3\\\\envs\\\\newxai\\\\lib\\\\ntpath.py'\n",
      "\n",
      "During handling of the above exception, another exception occurred:\n",
      "\n",
      "Traceback (most recent call last):\n",
      "  File \"_pydevd_bundle\\pydevd_cython_win32_39_64.pyx\", line 1548, in _pydevd_bundle.pydevd_cython_win32_39_64.ThreadTracer.__call__\n",
      "KeyError: 'C:\\\\Program Files\\\\JetBrains\\\\PyCharm 2022.3.1\\\\plugins\\\\python\\\\helpers\\\\pydev\\\\pydevd_file_utils.py'\n",
      "\n",
      "During handling of the above exception, another exception occurred:\n",
      "\n",
      "Traceback (most recent call last):\n",
      "  File \"C:\\Program Files\\JetBrains\\PyCharm 2022.3.1\\plugins\\python\\helpers\\pydev\\pydevd_file_utils.py\", line 586, in get_abs_path_real_path_and_base_from_frame\n",
      "    return NORM_PATHS_AND_BASE_CONTAINER[frame.f_code.co_filename]\n",
      "KeyError: 'C:\\\\Program Files\\\\JetBrains\\\\PyCharm 2022.3.1\\\\plugins\\\\python\\\\helpers\\\\pydev\\\\pydevd_file_utils.py'\n",
      "\n",
      "During handling of the above exception, another exception occurred:\n",
      "\n",
      "Traceback (most recent call last):\n",
      "  File \"_pydevd_bundle\\pydevd_cython_win32_39_64.pyx\", line 1550, in _pydevd_bundle.pydevd_cython_win32_39_64.ThreadTracer.__call__\n",
      "  File \"C:\\Program Files\\JetBrains\\PyCharm 2022.3.1\\plugins\\python\\helpers\\pydev\\pydevd_file_utils.py\", line 593, in get_abs_path_real_path_and_base_from_frame\n",
      "    if get_abs_path_real_path_and_base_from_file is None:  # Interpreter shutdown\n",
      "NameError: name 'get_abs_path_real_path_and_base_from_file' is not defined\n",
      "Traceback (most recent call last):\n",
      "  File \"C:\\Program Files\\JetBrains\\PyCharm 2022.3.1\\plugins\\python\\helpers\\pydev\\pydevd_file_utils.py\", line 230, in _NormPaths\n",
      "    return NORM_PATHS_CONTAINER[filename]\n",
      "KeyError: 'C:\\\\Users\\\\Isabe\\\\.julia\\\\conda\\\\3\\\\envs\\\\newxai\\\\lib\\\\ntpath.py'\n",
      "\n",
      "During handling of the above exception, another exception occurred:\n",
      "\n",
      "Traceback (most recent call last):\n",
      "  File \"_pydevd_bundle\\pydevd_cython_win32_39_64.pyx\", line 1548, in _pydevd_bundle.pydevd_cython_win32_39_64.ThreadTracer.__call__\n",
      "KeyError: 'C:\\\\Program Files\\\\JetBrains\\\\PyCharm 2022.3.1\\\\plugins\\\\python\\\\helpers\\\\pydev\\\\pydevd_file_utils.py'\n",
      "\n",
      "During handling of the above exception, another exception occurred:\n",
      "\n",
      "Traceback (most recent call last):\n",
      "  File \"C:\\Program Files\\JetBrains\\PyCharm 2022.3.1\\plugins\\python\\helpers\\pydev\\pydevd_file_utils.py\", line 586, in get_abs_path_real_path_and_base_from_frame\n",
      "    return NORM_PATHS_AND_BASE_CONTAINER[frame.f_code.co_filename]\n",
      "KeyError: 'C:\\\\Program Files\\\\JetBrains\\\\PyCharm 2022.3.1\\\\plugins\\\\python\\\\helpers\\\\pydev\\\\pydevd_file_utils.py'\n",
      "\n",
      "During handling of the above exception, another exception occurred:\n",
      "\n",
      "Traceback (most recent call last):\n",
      "  File \"_pydevd_bundle\\pydevd_cython_win32_39_64.pyx\", line 1550, in _pydevd_bundle.pydevd_cython_win32_39_64.ThreadTracer.__call__\n",
      "  File \"C:\\Program Files\\JetBrains\\PyCharm 2022.3.1\\plugins\\python\\helpers\\pydev\\pydevd_file_utils.py\", line 593, in get_abs_path_real_path_and_base_from_frame\n",
      "    if get_abs_path_real_path_and_base_from_file is None:  # Interpreter shutdown\n",
      "NameError: name 'get_abs_path_real_path_and_base_from_file' is not defined\n",
      "Traceback (most recent call last):\n",
      "  File \"C:\\Program Files\\JetBrains\\PyCharm 2022.3.1\\plugins\\python\\helpers\\pydev\\pydevd_file_utils.py\", line 230, in _NormPaths\n",
      "    return NORM_PATHS_CONTAINER[filename]\n",
      "KeyError: 'C:\\\\Users\\\\Isabe\\\\.julia\\\\conda\\\\3\\\\envs\\\\newxai\\\\lib\\\\ntpath.py'\n",
      "\n",
      "During handling of the above exception, another exception occurred:\n",
      "\n",
      "Traceback (most recent call last):\n",
      "  File \"_pydevd_bundle\\pydevd_cython_win32_39_64.pyx\", line 1548, in _pydevd_bundle.pydevd_cython_win32_39_64.ThreadTracer.__call__\n",
      "KeyError: 'C:\\\\Program Files\\\\JetBrains\\\\PyCharm 2022.3.1\\\\plugins\\\\python\\\\helpers\\\\pydev\\\\pydevd_file_utils.py'\n",
      "\n",
      "During handling of the above exception, another exception occurred:\n",
      "\n",
      "Traceback (most recent call last):\n",
      "  File \"C:\\Program Files\\JetBrains\\PyCharm 2022.3.1\\plugins\\python\\helpers\\pydev\\pydevd_file_utils.py\", line 586, in get_abs_path_real_path_and_base_from_frame\n",
      "    return NORM_PATHS_AND_BASE_CONTAINER[frame.f_code.co_filename]\n",
      "KeyError: 'C:\\\\Program Files\\\\JetBrains\\\\PyCharm 2022.3.1\\\\plugins\\\\python\\\\helpers\\\\pydev\\\\pydevd_file_utils.py'\n",
      "\n",
      "During handling of the above exception, another exception occurred:\n",
      "\n",
      "Traceback (most recent call last):\n",
      "  File \"_pydevd_bundle\\pydevd_cython_win32_39_64.pyx\", line 1550, in _pydevd_bundle.pydevd_cython_win32_39_64.ThreadTracer.__call__\n",
      "  File \"C:\\Program Files\\JetBrains\\PyCharm 2022.3.1\\plugins\\python\\helpers\\pydev\\pydevd_file_utils.py\", line 593, in get_abs_path_real_path_and_base_from_frame\n",
      "    if get_abs_path_real_path_and_base_from_file is None:  # Interpreter shutdown\n",
      "NameError: name 'get_abs_path_real_path_and_base_from_file' is not defined\n",
      "Traceback (most recent call last):\n",
      "  File \"_pydevd_bundle\\pydevd_cython_win32_39_64.pyx\", line 1548, in _pydevd_bundle.pydevd_cython_win32_39_64.ThreadTracer.__call__\n",
      "KeyError: 'C:\\\\Program Files\\\\JetBrains\\\\PyCharm 2022.3.1\\\\plugins\\\\python\\\\helpers\\\\pydev\\\\pydevd_file_utils.py'\n",
      "\n",
      "During handling of the above exception, another exception occurred:\n",
      "\n",
      "Traceback (most recent call last):\n",
      "  File \"C:\\Program Files\\JetBrains\\PyCharm 2022.3.1\\plugins\\python\\helpers\\pydev\\pydevd_file_utils.py\", line 586, in get_abs_path_real_path_and_base_from_frame\n",
      "    return NORM_PATHS_AND_BASE_CONTAINER[frame.f_code.co_filename]\n",
      "KeyError: 'C:\\\\Program Files\\\\JetBrains\\\\PyCharm 2022.3.1\\\\plugins\\\\python\\\\helpers\\\\pydev\\\\pydevd_file_utils.py'\n",
      "\n",
      "During handling of the above exception, another exception occurred:\n",
      "\n",
      "Traceback (most recent call last):\n",
      "  File \"_pydevd_bundle\\pydevd_cython_win32_39_64.pyx\", line 1550, in _pydevd_bundle.pydevd_cython_win32_39_64.ThreadTracer.__call__\n",
      "  File \"C:\\Program Files\\JetBrains\\PyCharm 2022.3.1\\plugins\\python\\helpers\\pydev\\pydevd_file_utils.py\", line 593, in get_abs_path_real_path_and_base_from_frame\n",
      "    if get_abs_path_real_path_and_base_from_file is None:  # Interpreter shutdown\n",
      "NameError: name 'get_abs_path_real_path_and_base_from_file' is not defined\n",
      "Traceback (most recent call last):\n",
      "  File \"_pydevd_bundle\\pydevd_cython_win32_39_64.pyx\", line 1548, in _pydevd_bundle.pydevd_cython_win32_39_64.ThreadTracer.__call__\n",
      "KeyError: 'C:\\\\Program Files\\\\JetBrains\\\\PyCharm 2022.3.1\\\\plugins\\\\python\\\\helpers\\\\pydev\\\\pydevd_file_utils.py'\n",
      "\n",
      "During handling of the above exception, another exception occurred:\n",
      "\n",
      "Traceback (most recent call last):\n",
      "  File \"C:\\Program Files\\JetBrains\\PyCharm 2022.3.1\\plugins\\python\\helpers\\pydev\\pydevd_file_utils.py\", line 586, in get_abs_path_real_path_and_base_from_frame\n",
      "    return NORM_PATHS_AND_BASE_CONTAINER[frame.f_code.co_filename]\n",
      "KeyError: 'C:\\\\Program Files\\\\JetBrains\\\\PyCharm 2022.3.1\\\\plugins\\\\python\\\\helpers\\\\pydev\\\\pydevd_file_utils.py'\n",
      "\n",
      "During handling of the above exception, another exception occurred:\n",
      "\n",
      "Traceback (most recent call last):\n",
      "  File \"_pydevd_bundle\\pydevd_cython_win32_39_64.pyx\", line 1550, in _pydevd_bundle.pydevd_cython_win32_39_64.ThreadTracer.__call__\n",
      "  File \"C:\\Program Files\\JetBrains\\PyCharm 2022.3.1\\plugins\\python\\helpers\\pydev\\pydevd_file_utils.py\", line 593, in get_abs_path_real_path_and_base_from_frame\n",
      "    if get_abs_path_real_path_and_base_from_file is None:  # Interpreter shutdown\n",
      "NameError: name 'get_abs_path_real_path_and_base_from_file' is not defined\n",
      "[autoreload of pydevd failed: Traceback (most recent call last):\n",
      "  File \"C:\\Users\\Isabe\\.julia\\conda\\3\\envs\\newxai\\lib\\site-packages\\IPython\\extensions\\autoreload.py\", line 273, in check\n",
      "    superreload(m, reload, self.old_objects)\n",
      "  File \"C:\\Users\\Isabe\\.julia\\conda\\3\\envs\\newxai\\lib\\site-packages\\IPython\\extensions\\autoreload.py\", line 496, in superreload\n",
      "    update_generic(old_obj, new_obj)\n",
      "  File \"C:\\Users\\Isabe\\.julia\\conda\\3\\envs\\newxai\\lib\\site-packages\\IPython\\extensions\\autoreload.py\", line 393, in update_generic\n",
      "    update(a, b)\n",
      "  File \"C:\\Users\\Isabe\\.julia\\conda\\3\\envs\\newxai\\lib\\site-packages\\IPython\\extensions\\autoreload.py\", line 361, in update_class\n",
      "    update_instances(old, new)\n",
      "  File \"C:\\Users\\Isabe\\.julia\\conda\\3\\envs\\newxai\\lib\\site-packages\\IPython\\extensions\\autoreload.py\", line 319, in update_instances\n",
      "    object.__setattr__(ref, \"__class__\", new)\n",
      "TypeError: __class__ assignment: 'ThreadsSuspendedSingleNotification' object layout differs from 'ThreadsSuspendedSingleNotification'\n",
      "]\n",
      "Traceback (most recent call last):\n",
      "  File \"_pydevd_bundle\\pydevd_cython_win32_39_64.pyx\", line 914, in _pydevd_bundle.pydevd_cython_win32_39_64.PyDBFrame.trace_dispatch\n",
      "  File \"C:\\Program Files\\JetBrains\\PyCharm 2022.3.1\\plugins\\python\\helpers-pro\\jupyter_debug\\pydev_jupyter_plugin.py\", line 242, in suspend\n",
      "    return suspend_jupyter(pydb, thread, frame)\n",
      "  File \"C:\\Program Files\\JetBrains\\PyCharm 2022.3.1\\plugins\\python\\helpers-pro\\jupyter_debug\\pydev_jupyter_plugin.py\", line 191, in suspend_jupyter\n",
      "    pydb.set_suspend(thread, cmd)\n",
      "  File \"C:\\Program Files\\JetBrains\\PyCharm 2022.3.1\\plugins\\python\\helpers\\pydev\\pydevd.py\", line 971, in set_suspend\n",
      "    self._threads_suspended_single_notification.increment_suspend_time()\n",
      "  File \"C:\\Program Files\\JetBrains\\PyCharm 2022.3.1\\plugins\\python\\helpers\\pydev\\pydevd.py\", line 275, in increment_suspend_time\n",
      "    with self._lock:\n",
      "TypeError: descriptor '_lock' for 'ThreadsSuspendedSingleNotification' objects doesn't apply to a 'ThreadsSuspendedSingleNotification' object\n"
     ]
    },
    {
     "ename": "TypeError",
     "evalue": "descriptor '_lock' for 'ThreadsSuspendedSingleNotification' objects doesn't apply to a 'ThreadsSuspendedSingleNotification' object",
     "output_type": "error",
     "traceback": [
      "\u001B[1;31m---------------------------------------------------------------------------\u001B[0m",
      "\u001B[1;31mTypeError\u001B[0m                                 Traceback (most recent call last)",
      "Cell \u001B[1;32mIn[5], line 2\u001B[0m\n\u001B[0;32m      1\u001B[0m \u001B[38;5;66;03m# pydev_debug_cell\u001B[39;00m\n\u001B[1;32m----> 2\u001B[0m \u001B[43mcreate_class_cluster\u001B[49m(model)\n",
      "Cell \u001B[1;32mIn[5], line 2\u001B[0m\n\u001B[0;32m      1\u001B[0m \u001B[38;5;66;03m# pydev_debug_cell\u001B[39;00m\n\u001B[1;32m----> 2\u001B[0m \u001B[43mcreate_class_cluster\u001B[49m(model)\n",
      "File \u001B[1;32m_pydevd_bundle\\pydevd_cython_win32_39_64.pyx:1179\u001B[0m, in \u001B[0;36m_pydevd_bundle.pydevd_cython_win32_39_64.SafeCallWrapper.__call__\u001B[1;34m()\u001B[0m\n",
      "File \u001B[1;32m_pydevd_bundle\\pydevd_cython_win32_39_64.pyx:620\u001B[0m, in \u001B[0;36m_pydevd_bundle.pydevd_cython_win32_39_64.PyDBFrame.trace_dispatch\u001B[1;34m()\u001B[0m\n",
      "File \u001B[1;32m_pydevd_bundle\\pydevd_cython_win32_39_64.pyx:932\u001B[0m, in \u001B[0;36m_pydevd_bundle.pydevd_cython_win32_39_64.PyDBFrame.trace_dispatch\u001B[1;34m()\u001B[0m\n",
      "File \u001B[1;32m_pydevd_bundle\\pydevd_cython_win32_39_64.pyx:914\u001B[0m, in \u001B[0;36m_pydevd_bundle.pydevd_cython_win32_39_64.PyDBFrame.trace_dispatch\u001B[1;34m()\u001B[0m\n",
      "File \u001B[1;32mC:\\Program Files\\JetBrains\\PyCharm 2022.3.1\\plugins\\python\\helpers-pro\\jupyter_debug\\pydev_jupyter_plugin.py:242\u001B[0m, in \u001B[0;36msuspend\u001B[1;34m(plugin, pydb, thread, frame, bp_type)\u001B[0m\n\u001B[0;32m    240\u001B[0m \u001B[38;5;28;01mdef\u001B[39;00m \u001B[38;5;21msuspend\u001B[39m(plugin, pydb, thread, frame, bp_type):\n\u001B[0;32m    241\u001B[0m     \u001B[38;5;28;01mif\u001B[39;00m bp_type \u001B[38;5;241m==\u001B[39m \u001B[38;5;124m'\u001B[39m\u001B[38;5;124mjupyter-line\u001B[39m\u001B[38;5;124m'\u001B[39m \u001B[38;5;129;01mand\u001B[39;00m _is_inside_jupyter_cell(frame, pydb):\n\u001B[1;32m--> 242\u001B[0m         \u001B[38;5;28;01mreturn\u001B[39;00m \u001B[43msuspend_jupyter\u001B[49m\u001B[43m(\u001B[49m\u001B[43mpydb\u001B[49m\u001B[43m,\u001B[49m\u001B[43m \u001B[49m\u001B[43mthread\u001B[49m\u001B[43m,\u001B[49m\u001B[43m \u001B[49m\u001B[43mframe\u001B[49m\u001B[43m)\u001B[49m\n\u001B[0;32m    243\u001B[0m     \u001B[38;5;28;01mreturn\u001B[39;00m \u001B[38;5;28;01mNone\u001B[39;00m\n",
      "File \u001B[1;32mC:\\Program Files\\JetBrains\\PyCharm 2022.3.1\\plugins\\python\\helpers-pro\\jupyter_debug\\pydev_jupyter_plugin.py:191\u001B[0m, in \u001B[0;36msuspend_jupyter\u001B[1;34m(pydb, thread, frame, cmd, message)\u001B[0m\n\u001B[0;32m    189\u001B[0m \u001B[38;5;28;01mdef\u001B[39;00m \u001B[38;5;21msuspend_jupyter\u001B[39m(pydb, thread, frame, cmd\u001B[38;5;241m=\u001B[39mCMD_SET_BREAK, message\u001B[38;5;241m=\u001B[39m\u001B[38;5;28;01mNone\u001B[39;00m):\n\u001B[0;32m    190\u001B[0m     frame \u001B[38;5;241m=\u001B[39m JupyterFrame(frame, pydb)\n\u001B[1;32m--> 191\u001B[0m     \u001B[43mpydb\u001B[49m\u001B[38;5;241;43m.\u001B[39;49m\u001B[43mset_suspend\u001B[49m\u001B[43m(\u001B[49m\u001B[43mthread\u001B[49m\u001B[43m,\u001B[49m\u001B[43m \u001B[49m\u001B[43mcmd\u001B[49m\u001B[43m)\u001B[49m\n\u001B[0;32m    192\u001B[0m     thread\u001B[38;5;241m.\u001B[39madditional_info\u001B[38;5;241m.\u001B[39msuspend_type \u001B[38;5;241m=\u001B[39m JUPYTER_SUSPEND\n\u001B[0;32m    193\u001B[0m     \u001B[38;5;28;01mif\u001B[39;00m cmd \u001B[38;5;241m==\u001B[39m CMD_ADD_EXCEPTION_BREAK:\n\u001B[0;32m    194\u001B[0m         \u001B[38;5;66;03m# send exception name as message\u001B[39;00m\n",
      "File \u001B[1;32mC:\\Program Files\\JetBrains\\PyCharm 2022.3.1\\plugins\\python\\helpers\\pydev\\pydevd.py:971\u001B[0m, in \u001B[0;36mPyDB.set_suspend\u001B[1;34m(self, thread, stop_reason, suspend_other_threads, is_pause)\u001B[0m\n\u001B[0;32m    955\u001B[0m \u001B[38;5;28;01mdef\u001B[39;00m \u001B[38;5;21mset_suspend\u001B[39m(\u001B[38;5;28mself\u001B[39m, thread, stop_reason, suspend_other_threads\u001B[38;5;241m=\u001B[39m\u001B[38;5;28;01mFalse\u001B[39;00m, is_pause\u001B[38;5;241m=\u001B[39m\u001B[38;5;28;01mFalse\u001B[39;00m):\n\u001B[0;32m    956\u001B[0m \u001B[38;5;250m    \u001B[39m\u001B[38;5;124;03m'''\u001B[39;00m\n\u001B[0;32m    957\u001B[0m \u001B[38;5;124;03m    :param thread:\u001B[39;00m\n\u001B[0;32m    958\u001B[0m \u001B[38;5;124;03m        The thread which should be suspended.\u001B[39;00m\n\u001B[1;32m   (...)\u001B[0m\n\u001B[0;32m    969\u001B[0m \u001B[38;5;124;03m        thread paused.\u001B[39;00m\n\u001B[0;32m    970\u001B[0m \u001B[38;5;124;03m    '''\u001B[39;00m\n\u001B[1;32m--> 971\u001B[0m     \u001B[38;5;28;43mself\u001B[39;49m\u001B[38;5;241;43m.\u001B[39;49m\u001B[43m_threads_suspended_single_notification\u001B[49m\u001B[38;5;241;43m.\u001B[39;49m\u001B[43mincrement_suspend_time\u001B[49m\u001B[43m(\u001B[49m\u001B[43m)\u001B[49m\n\u001B[0;32m    972\u001B[0m     \u001B[38;5;28;01mif\u001B[39;00m is_pause:\n\u001B[0;32m    973\u001B[0m         \u001B[38;5;28mself\u001B[39m\u001B[38;5;241m.\u001B[39m_threads_suspended_single_notification\u001B[38;5;241m.\u001B[39mon_pause()\n",
      "File \u001B[1;32mC:\\Program Files\\JetBrains\\PyCharm 2022.3.1\\plugins\\python\\helpers\\pydev\\pydevd.py:275\u001B[0m, in \u001B[0;36mAbstractSingleNotificationBehavior.increment_suspend_time\u001B[1;34m(self)\u001B[0m\n\u001B[0;32m    274\u001B[0m \u001B[38;5;28;01mdef\u001B[39;00m \u001B[38;5;21mincrement_suspend_time\u001B[39m(\u001B[38;5;28mself\u001B[39m):\n\u001B[1;32m--> 275\u001B[0m     \u001B[38;5;28;01mwith\u001B[39;00m \u001B[38;5;28;43mself\u001B[39;49m\u001B[38;5;241;43m.\u001B[39;49m\u001B[43m_lock\u001B[49m:\n\u001B[0;32m    276\u001B[0m         \u001B[38;5;28mself\u001B[39m\u001B[38;5;241m.\u001B[39m_suspend_time_request \u001B[38;5;241m=\u001B[39m \u001B[38;5;28mself\u001B[39m\u001B[38;5;241m.\u001B[39m_next_request_time()\n",
      "\u001B[1;31mTypeError\u001B[0m: descriptor '_lock' for 'ThreadsSuspendedSingleNotification' objects doesn't apply to a 'ThreadsSuspendedSingleNotification' object"
     ]
    }
   ],
   "source": [
    "\n",
    "create_class_cluster(model)"
   ],
   "metadata": {
    "collapsed": false
   }
  }
 ],
 "metadata": {
  "kernelspec": {
   "display_name": "Python 3",
   "language": "python",
   "name": "python3"
  },
  "language_info": {
   "codemirror_mode": {
    "name": "ipython",
    "version": 2
   },
   "file_extension": ".py",
   "mimetype": "text/x-python",
   "name": "python",
   "nbconvert_exporter": "python",
   "pygments_lexer": "ipython2",
   "version": "2.7.6"
  }
 },
 "nbformat": 4,
 "nbformat_minor": 0
}
